Workbook
Name スライサー_部屋: #N/A
Name 実施有無: #REF!
Name 判定: [1]結果!$AU$52:$AU$54

Sheet 試験装置・計測器一覧表
AQ1: =_xlfn.SHEET()&"/"&_xlfn.SHEETS() -> 1/4
AE2: № | AH2: =#REF! -> #REF!
C3: =#REF! -> #REF! | AE3: 作 成 | AH3: =#REF! -> #REF!
C4: 試験装置・計測器一覧表
D6: <環境/ 部屋>
D7: 104_B1F_南暗室2
D13: ＜常設設備＞
D14: 名称 | M14: メーカ名 | U14: 全社連番 | AA14: 管理No. | AI14: 定期検査有効期限
M15: 型式 | AA15: 管理部署 | AI15: 使用期間
D16: =IF(抽出!A2<>"", 抽出!A2, "") -> 電波暗室2 | M16: =IFERROR(VLOOKUP($D16, master!$B:$H, 2,FALSE), "") -> 日本シールドエンクロージャ | U16: =IFERROR(VLOOKUP($D16, master!$B:$H, 4,FALSE), "") -> 100011169747 | AA16: =IFERROR(VLOOKUP($D16, master!$B:$H, 5,FALSE), "") -> 206192 | AI16: =IFERROR(VLOOKUP($D16, master!$B:$H, 7,FALSE), "") -> 46691
M17: =IFERROR(VLOOKUP($D16, master!$B:$H, 3,FALSE), "") -> J-NP-AR型 | AA17: =IFERROR(VLOOKUP($D16, master!$B:$H, 6,FALSE), "") -> モビエレ試験評価部 | AI17: =IFERROR(VLOOKUP($D16, master!$B:$H, 8,FALSE), "")
D18: =IF(抽出!A3<>"", 抽出!A3, "") -> EMIテストレシーバ | M18: =IFERROR(VLOOKUP($D18, master!$B:$H, 2,FALSE), "") -> ROHDE＆SCHWARZ | U18: =IFERROR(VLOOKUP($D18, master!$B:$H, 4,FALSE), "") -> 100011154974 | AA18: =IFERROR(VLOOKUP($D18, master!$B:$H, 5,FALSE), "") -> SXZS5050 | AI18: =IFERROR(VLOOKUP($D18, master!$B:$H, 7,FALSE), "") -> 46418
M19: =IFERROR(VLOOKUP($D18, master!$B:$H, 3,FALSE), "") -> ESW8 | AA19: =IFERROR(VLOOKUP($D18, master!$B:$H, 6,FALSE), "") -> モビエレ試験評価部 | AI19: =IFERROR(VLOOKUP($D18, master!$B:$H, 8,FALSE), "")
D20: =IF(抽出!A4<>"", 抽出!A6, "") -> バイコニカルアンテナ | M20: =IFERROR(VLOOKUP($D20, master!$B:$H, 2,FALSE), "") -> SCHWARZBECK | U20: =IFERROR(VLOOKUP($D20, master!$B:$H, 4,FALSE), "") -> 100010229316 | AA20: =IFERROR(VLOOKUP($D20, master!$B:$H, 5,FALSE), "") -> S ZS3471 | AI20: =IFERROR(VLOOKUP($D20, master!$B:$H, 7,FALSE), "") -> 46387
M21: =IFERROR(VLOOKUP($D20, master!$B:$H, 3,FALSE), "") -> BBA9106+VHA9103 | AA21: =IFERROR(VLOOKUP($D20, master!$B:$H, 6,FALSE), "") -> モビエレ試験評価部 | AI21: =IFERROR(VLOOKUP($D20, master!$B:$H, 8,FALSE), "")
D22: =IF(抽出!A8<>"", 抽出!A4, "") -> スペクトラムアナライザ | M22: =IFERROR(VLOOKUP($D22, master!$B:$H, 2,FALSE), "") -> Agilent Technologies | U22: =IFERROR(VLOOKUP($D22, master!$B:$H, 4,FALSE), "") -> 100011224401 | AA22: =IFERROR(VLOOKUP($D22, master!$B:$H, 5,FALSE), "") -> SXSA1780 | AI22: =IFERROR(VLOOKUP($D22, master!$B:$H, 7,FALSE), "") -> 46418
M23: =IFERROR(VLOOKUP($D22, master!$B:$H, 3,FALSE), "") -> N9020A | AA23: =IFERROR(VLOOKUP($D22, master!$B:$H, 6,FALSE), "") -> モビエレ試験評価部 | AI23: =IFERROR(VLOOKUP($D22, master!$B:$H, 8,FALSE), "")
D24: =IF(抽出!A5<>"", 抽出!A5, "") -> アクティブロッドアンテナ | M24: =IFERROR(VLOOKUP($D24, master!$B:$H, 2,FALSE), "") -> ETS・LINDGREN | U24: =IFERROR(VLOOKUP($D24, master!$B:$H, 4,FALSE), "") -> 100011038580 | AA24: =IFERROR(VLOOKUP($D24, master!$B:$H, 5,FALSE), "") -> S ZS4319 | AI24: =IFERROR(VLOOKUP($D24, master!$B:$H, 7,FALSE), "") -> 46173
M25: =IFERROR(VLOOKUP($D24, master!$B:$H, 3,FALSE), "") -> 3301C | AA25: =IFERROR(VLOOKUP($D24, master!$B:$H, 6,FALSE), "") -> モビエレ試験評価部 | AI25: =IFERROR(VLOOKUP($D24, master!$B:$H, 8,FALSE), "")
D26: =IF(抽出!A6<>"", 抽出!A6, "") -> バイコニカルアンテナ | M26: =IFERROR(VLOOKUP($D26, master!$B:$H, 2,FALSE), "") -> SCHWARZBECK | U26: =IFERROR(VLOOKUP($D26, master!$B:$H, 4,FALSE), "") -> 100010229316 | AA26: =IFERROR(VLOOKUP($D26, master!$B:$H, 5,FALSE), "") -> S ZS3471 | AI26: =IFERROR(VLOOKUP($D26, master!$B:$H, 7,FALSE), "") -> 46387
M27: =IFERROR(VLOOKUP($D26, master!$B:$H, 3,FALSE), "") -> BBA9106+VHA9103 | AA27: =IFERROR(VLOOKUP($D26, master!$B:$H, 6,FALSE), "") -> モビエレ試験評価部 | AI27: =IFERROR(VLOOKUP($D26, master!$B:$H, 8,FALSE), "")
D28: =IF(抽出!A7<>"", 抽出!A7, "") -> ログペリオディックアンテナ | M28: =IFERROR(VLOOKUP($D28, master!$B:$H, 2,FALSE), "") -> 協立電子工業 | U28: =IFERROR(VLOOKUP($D28, master!$B:$H, 4,FALSE), "") -> 100010221941 | AA28: =IFERROR(VLOOKUP($D28, master!$B:$H, 5,FALSE), "") -> S ZS3472 | AI28: =IFERROR(VLOOKUP($D28, master!$B:$H, 7,FALSE), "") -> 46387
M29: =IFERROR(VLOOKUP($D28, master!$B:$H, 3,FALSE), "") -> KBA-623 | AA29: =IFERROR(VLOOKUP($D28, master!$B:$H, 6,FALSE), "") -> モビエレ試験評価部 | AI29: =IFERROR(VLOOKUP($D28, master!$B:$H, 8,FALSE), "")
D30: =IF(抽出!A8<>"", 抽出!A8, "") -> ダブルリッジホーンアンテナ[ BBHA ] | M30: =IFERROR(VLOOKUP($D30, master!$B:$H, 2,FALSE), "") -> SCHWARZBECK | U30: =IFERROR(VLOOKUP($D30, master!$B:$H, 4,FALSE), "") -> 100011177498 | AA30: =IFERROR(VLOOKUP($D30, master!$B:$H, 5,FALSE), "") -> SXZS5191 | AI30: =IFERROR(VLOOKUP($D30, master!$B:$H, 7,FALSE), "") -> 46387
M31: =IFERROR(VLOOKUP($D30, master!$B:$H, 3,FALSE), "") -> BBHA9120E | AA31: =IFERROR(VLOOKUP($D30, master!$B:$H, 6,FALSE), "") -> モビエレ試験評価部 | AI31: =IFERROR(VLOOKUP($D30, master!$B:$H, 8,FALSE), "")
D32: =IF(抽出!A12<>"", 抽出!A12, "") -> プリアンプ[ SONOMA ] | M32: =IFERROR(VLOOKUP($D32, master!$B:$H, 2,FALSE), "") -> Sonoma Instrument | U32: =IFERROR(VLOOKUP($D32, master!$B:$H, 4,FALSE), "") -> 100011197643 | AA32: =IFERROR(VLOOKUP($D32, master!$B:$H, 5,FALSE), "") -> ZXZZ6663 | AI32: =IFERROR(VLOOKUP($D32, master!$B:$H, 7,FALSE), "") -> 46418
M33: =IFERROR(VLOOKUP($D32, master!$B:$H, 3,FALSE), "") -> 310N | AA33: =IFERROR(VLOOKUP($D32, master!$B:$H, 6,FALSE), "") -> モビエレ試験評価部 | AI33: =IFERROR(VLOOKUP($D32, master!$B:$H, 8,FALSE), "")
D34: =IF(抽出!A13<>"", 抽出!A13, "") -> プリアンプ[ tsj ] | M34: =IFERROR(VLOOKUP($D34, master!$B:$H, 2,FALSE), "") -> tsj | U34: =IFERROR(VLOOKUP($D34, master!$B:$H, 4,FALSE), "") -> 100011177501 | AA34: =IFERROR(VLOOKUP($D34, master!$B:$H, 5,FALSE), "") -> SAMS0733 | AI34: =IFERROR(VLOOKUP($D34, master!$B:$H, 7,FALSE), "") -> 46418
M35: =IFERROR(VLOOKUP($D34, master!$B:$H, 3,FALSE), "") -> MLA-0108-j02 | AA35: =IFERROR(VLOOKUP($D34, master!$B:$H, 6,FALSE), "") -> モビエレ試験評価部 | AI35: =IFERROR(VLOOKUP($D34, master!$B:$H, 8,FALSE), "")
D36: =IF(抽出!A14<>"", 抽出!A14, "") -> プリアンプ[ 6cmループ用 ] | M36: =IFERROR(VLOOKUP($D36, master!$B:$H, 2,FALSE), "") -> 東陽テクニカ | U36: =IFERROR(VLOOKUP($D36, master!$B:$H, 4,FALSE), "") -> 100011051455 | AA36: =IFERROR(VLOOKUP($D36, master!$B:$H, 5,FALSE), "") -> SAMS0705 | AI36: =IFERROR(VLOOKUP($D36, master!$B:$H, 7,FALSE), "") -> 46418
M37: =IFERROR(VLOOKUP($D36, master!$B:$H, 3,FALSE), "") -> TPA-AM1431 | AA37: =IFERROR(VLOOKUP($D36, master!$B:$H, 6,FALSE), "") -> モビエレ試験評価部 | AI37: =IFERROR(VLOOKUP($D36, master!$B:$H, 8,FALSE), "")
D38: =IF(抽出!A17<>"", 抽出!A17, "") -> 電流プローブ[ 94111-1] | M38: =IFERROR(VLOOKUP($D38, master!$B:$H, 2,FALSE), "") -> ETS・LINDGREN | U38: =IFERROR(VLOOKUP($D38, master!$B:$H, 4,FALSE), "") -> 100010086208 | AA38: =IFERROR(VLOOKUP($D38, master!$B:$H, 5,FALSE), "") -> S CP0916 | AI38: =IFERROR(VLOOKUP($D38, master!$B:$H, 7,FALSE), "") -> 46418
M39: =IFERROR(VLOOKUP($D38, master!$B:$H, 3,FALSE), "") -> 94111-1 | AA39: =IFERROR(VLOOKUP($D38, master!$B:$H, 6,FALSE), "") -> モビエレ試験評価部 | AI39: =IFERROR(VLOOKUP($D38, master!$B:$H, 8,FALSE), "")
D40: =IF(抽出!A18<>"", 抽出!A18, "") -> 3dBアッテネータ | M40: =IFERROR(VLOOKUP($D40, master!$B:$H, 2,FALSE), "") -> JFW Industries | U40: =IFERROR(VLOOKUP($D40, master!$B:$H, 4,FALSE), "") -> 100011208489 | AA40: =IFERROR(VLOOKUP($D40, master!$B:$H, 5,FALSE), "") -> - | AI40: =IFERROR(VLOOKUP($D40, master!$B:$H, 7,FALSE), "") -> 46418
M41: =IFERROR(VLOOKUP($D40, master!$B:$H, 3,FALSE), "") -> 50HF-003N | AA41: =IFERROR(VLOOKUP($D40, master!$B:$H, 6,FALSE), "") -> モビエレ試験評価部 | AI41: =IFERROR(VLOOKUP($D40, master!$B:$H, 8,FALSE), "")
D44: ＜標準ベンチ・ベンチワイヤ・SWボックス＞
D45: 名称 | M45: メーカ名 | U45: 全社連番 | AA45: 管理No. | AI45: 定期検査有効期限
M46: 型式 | AA46: 管理部署 | AI46: 使用期間
D64: ＜外付け負荷等＞
D65: 名称 | M65: メーカ名 | U65: 全社連番 | AA65: 管理No. | AI65: 定期検査有効期限
...

Sheet master
A1: 部屋 | B1: 名称 | C1: メーカ | D1: 型式 | E1: 全社連番 | F1: 管理No. | G1: 管理部署 | H1: 有効期限
A2: 104_B1F_南暗室2 | B2: 電波暗室2 | C2: 日本シールドエンクロージャ | D2: J-NP-AR型 | E2: 100011169747 | F2: 206192 | G2: モビエレ試験評価部 | H2: 46691
A3: 104_B1F_南暗室2 | B3: EMIテストレシーバ | C3: ROHDE＆SCHWARZ | D3: ESW8 | E3: 100011154974 | F3: SXZS5050 | G3: モビエレ試験評価部 | H3: 46418
A4: 104_B1F_南暗室2 | B4: スペクトラムアナライザ | C4: Agilent Technologies | D4: N9020A | E4: 100011224401 | F4: SXSA1780 | G4: モビエレ試験評価部 | H4: 46418 | J4: 18.6
A5: 104_B1F_南暗室2 | B5: アクティブロッドアンテナ | C5: ETS・LINDGREN | D5: 3301C | E5: 100011038580 | F5: S ZS4319 | G5: モビエレ試験評価部 | H5: 46173
A6: 104_B1F_南暗室2 | B6: バイコニカルアンテナ | C6: SCHWARZBECK | D6: BBA9106+VHA9103 | E6: 100010229316 | F6: S ZS3471 | G6: モビエレ試験評価部 | H6: 46387
A7: 104_B1F_南暗室2 | B7: ログペリオディックアンテナ | C7: 協立電子工業 | D7: KBA-623 | E7: 100010221941 | F7: S ZS3472 | G7: モビエレ試験評価部 | H7: 46387
A8: 104_B1F_南暗室2 | B8: ダブルリッジホーンアンテナ[ BBHA ] | C8: SCHWARZBECK | D8: BBHA9120E | E8: 100011177498 | F8: SXZS5191 | G8: モビエレ試験評価部 | H8: 46387
A9: 104_B1F_南暗室2 | B9: ダブルリッジホーンアンテナ[ 3115 ] | C9: ETS・LINDGREN | D9: 3115 | E9: 100011224398 | F9: SXZS5713 | G9: モビエレ試験評価部 | H9: 46387
A10: 104_B1F_南暗室2 | B10: 60cmループアンテナ | C10: ETS・LINDGREN | D10: 6502 | E10: 100011191955 | F10: SXZS5372 | G10: モビエレ試験評価部 | H10: 46418
A11: 104_B1F_南暗室2 | B11: 6cmループアンテナ（暗室2用） | C11: ROHDE＆SCHWARZ | D11: HZ-11/05 | E11: 100010091069 | F11: S ZS3488 | G11: モビエレ試験評価部 | H11: 45901
A12: 104_B1F_南暗室2 | B12: プリアンプ[ SONOMA ] | C12: Sonoma Instrument | D12: 310N | E12: 100011197643 | F12: ZXZZ6663 | G12: モビエレ試験評価部 | H12: 46418
A13: 104_B1F_南暗室2 | B13: プリアンプ[ tsj ] | C13: tsj | D13: MLA-0108-j02 | E13: 100011177501 | F13: SAMS0733 | G13: モビエレ試験評価部 | H13: 46418
A14: 104_B1F_南暗室2 | B14: プリアンプ[ 6cmループ用 ] | C14: 東陽テクニカ | D14: TPA-AM1431 | E14: 100011051455 | F14: SAMS0705 | G14: モビエレ試験評価部 | H14: 46418
A15: 104_B1F_南暗室2 | B15: 暗室内同軸ケーブル | C15: 潤工社 | D15: MWX322 | E15: 100011224055 | F15: 2401G001 | G15: モビエレ試験評価部 | H15: 46418
A16: 104_B1F_南暗室2 | B16: 電流プローブ[ 91550-1 ] | C16: ETS・LINDGREN | D16: 91550-1 | E16: 100010234620 | F16: 00156744 | G16: モビエレ試験評価部 | H16: 46418
A17: 104_B1F_南暗室2 | B17: 電流プローブ[ 94111-1] | C17: ETS・LINDGREN | D17: 94111-1 | E17: 100010086208 | F17: S CP0916 | G17: モビエレ試験評価部 | H17: 46418
A18: 104_B1F_南暗室2 | B18: 3dBアッテネータ | C18: JFW Industries | D18: 50HF-003N | E18: 100011208489 | F18: - | G18: モビエレ試験評価部 | H18: 46418
A19: 104_B1F_南暗室2 | B19: LISN | C19: SCHWARZBECK | D19: NNBM8124 | E19: 100011077788 | F19: Z ZZ6417 | G19: モビエレ試験評価部 | H19: 46418
A20: 104_B1F_南暗室2 | B20: LISN | C20: SCHWARZBECK | D20: NNBM8124 | E20: 100011077789 | F20: Z ZZ6418 | G20: モビエレ試験評価部 | H20: 46418
A21: 104_B1F_南暗室2 | B21: 50Ω 終端抵抗 | C21: - | D21: - | E21: - | F21: No.041 | G21: モビエレ試験評価部 | H21: 46418
A22: 104_B1F_南暗室2 | B22: 50Ω 終端抵抗 | C22: - | D22: - | E22: - | F22: No.042 | G22: モビエレ試験評価部 | H22: 46418
A23: 104_B1F_南暗室2 | B23: デジタルテスタ | C23: HIOKI | D23: DT4261 | E23: 100011228715 | F23: 240723089 | G23: モビエレ試験評価部 | H23: 46327
A24: 104_B1F_南暗室2 | B24: デジタル温湿度計 | C24: HIOKI | D24: LR5001 | E24: 100011084972 | F24: 180824829 | G24: モビエレ試験評価部 | H24: 46234
A25: 104_B1F_北暗室12 | B25: 電波暗室12 | C25: 日本シールドエンクロージャ | D25: J-NP-AR型 | E25: 100011169742 | F25: 2015010 | G25: モビエレ試験評価部 | H25: 46691
A26: 104_B1F_北暗室12 | B26: EMIテストレシーバ | C26: ROHDE＆SCHWARZ | D26: ESW8 | E26: 100011145062 | F26: SXZS4922 | G26: モビエレ試験評価部 | H26: 46538
A27: 104_B1F_北暗室12 | B27: スペクトラムアナライザ | C27: Agilent Technologies | D27: N9020A | E27: 100011169425 | F27: MY52090696 | G27: モビエレ試験評価部 | H27: 46507
A28: 104_B1F_北暗室12 | B28: アクティブロッドアンテナ | C28: ETS・LINDGREN | D28: 3301C | E28: 100011038580 | F28: S ZS4319 | G28: モビエレ試験評価部 | H28: 46173
A29: 104_B1F_北暗室12 | B29: バイコニカルアンテナ | C29: SCHWARZBECK | D29: BBA9106+VHA9103B | E29: 100011188895 | F29: S ZS3805 | G29: モビエレ試験評価部 | H29: 46173
A30: 104_B1F_北暗室12 | B30: ログペリオディックアンテナ | C30: 協立電子工業 | D30: KBA-623 | E30: 100011188896 | F30: S ZS3805 | G30: モビエレ試験評価部 | H30: 46113
A31: 104_B1F_北暗室12 | B31: ダブルリッジホーンアンテナ[ BBHA ] | C31: SCHWARZBECK | D31: BBHA9120E | E31: 100011152115 | F31: SXZS5025 | G31: モビエレ試験評価部 | H31: 46173
A32: 104_B1F_北暗室12 | B32: ダブルリッジホーンアンテナ[ 3115 ] | C32: ETS・LINDGREN | D32: 3115 | E32: 100010096890 | F32: S ZS3805 | G32: モビエレ試験評価部 | H32: 46173
A33: 104_B1F_北暗室12 | B33: 60cmループアンテナ | C33: ETS・LINDGREN | D33: 6502 | E33: 100011191956 | F33: SXZS5373 | G33: モビエレ試験評価部 | H33: 46173
A34: 104_B1F_北暗室12 | B34: 6cmループアンテナ（暗室2用） | C34: ROHDE＆SCHWARZ | D34: HZ-11/05 | E34: 100010091069 | F34: S ZS3488 | G34: モビエレ試験評価部 | H34: 45930
A35: 104_B1F_北暗室12 | B35: プリアンプ[ SONOMA ] | C35: Sonoma Instrument | D35: 310N | E35: 100011197645 | F35: ZXZZ6665 | G35: モビエレ試験評価部 | H35: 46173
A36: 104_B1F_北暗室12 | B36: プリアンプ[ tsj ] | C36: tsj | D36: MLA-0108-j02 | E36: 100011177500 | F36: SAMS0732 | G36: モビエレ試験評価部 | H36: 46143
A37: 104_B1F_北暗室12 | B37: プリアンプ[ 6cmループ用 ] | C37: 東陽テクニカ | D37: TPA-AM1431 | E37: 100011051456 | F37: SAMS0706 | G37: モビエレ試験評価部 | H37: 46418
A38: 104_B1F_北暗室12 | B38: 暗室内同軸ケーブル | C38: 潤工社 | D38: MWX322 | E38: 100011208487 | F38: 2208G004 | G38: モビエレ試験評価部 | H38: 46173
A39: 104_B1F_北暗室12 | B39: 3dBアッテネータ | C39: JFW Industries | D39: 50HF-003N | E39: 100011208486 | F39: - | G39: モビエレ試験評価部 | H39: 46173
A40: 104_B1F_北暗室12 | B40: LISN | C40: SCHWARZBECK | D40: NNBM8124 | E40: 100011208022 | F40: IMA 7042 | G40: モビエレ試験評価部 | H40: 46538
...

Sheet 抽出
A1: 名称
A2: {=_xlfn._xlws.FILTER(master!B:B, (master!$A:$A=試験装置・計測器一覧表!$D$7), "該当なし")} -> 電波暗室2
A3: EMIテストレシーバ
A4: スペクトラムアナライザ
A5: アクティブロッドアンテナ
A6: バイコニカルアンテナ
A7: ログペリオディックアンテナ
A8: ダブルリッジホーンアンテナ[ BBHA ]
A9: ダブルリッジホーンアンテナ[ 3115 ]
A10: 60cmループアンテナ
A11: 6cmループアンテナ（暗室2用）
A12: プリアンプ[ SONOMA ]
A13: プリアンプ[ tsj ]
A14: プリアンプ[ 6cmループ用 ]
... A24: デジタル温湿度計

Sheet 試験備品一覧表
AQ1: =_xlfn.SHEET()&"/"&_xlfn.SHEETS() -> 4/4
AE2: № | AH2: =#REF! -> #REF!
C3: =#REF! -> #REF! | AE3: 作 成 | AH3: =#REF! -> #REF!
C4: 試験備品一覧表
D6: ＜試験備品一覧表＞
D7: 名称 | M7: ﾒｰｶ名 | T7: 管理№ | Z7: 定期検査有効期限 | AH7: 使用期間
M8: 型式 | Z8: 管理部署 | AH8: 使用者
D51: ※2 バッテリ電圧
D52: 日付 | H52: ﾊﾞｯﾃﾘNo. | N52: バッテリ電圧[V] | V52: 温湿度
N54: 試験前 | R54: 試験後 | V54: 温度[℃] | Z54: 湿度[%]
